<?xml version="1.0" encoding="UTF-8"?><testsuite name="nosetests" tests="1" errors="1" failures="0" skip="0"><testcase classname="concTests.testIWT_AVW.testIWT_AVW" name="test_site1" time="1.007"><error type="urllib2.URLError" message="&lt;urlopen error [Errno 10061] No connection could be made because the target machine actively refused it&gt;"><![CDATA[Traceback (most recent call last):
  File "C:\Python27\lib\unittest\case.py", line 318, in run
    self.setUp()
  File "C:\Users\pdam\git\IliaK_Concurrent\src\concTests\testIWT_AVW.py", line 57, in setUp
    self.driver = webdriver.Remote(command_executor='http://localhost:'+str(hostport)+'/wd/hub',  desired_capabilities=webdriver.DesiredCapabilities.ANDROID)
  File "C:\Python27\lib\site-packages\selenium-2.31.0-py2.7.egg\selenium\webdriver\remote\webdriver.py", line 67, in __init__
    self.start_session(desired_capabilities, browser_profile)
  File "C:\Python27\lib\site-packages\selenium-2.31.0-py2.7.egg\selenium\webdriver\remote\webdriver.py", line 109, in start_session
    'desiredCapabilities': desired_capabilities,
  File "C:\Python27\lib\site-packages\selenium-2.31.0-py2.7.egg\selenium\webdriver\remote\webdriver.py", line 158, in execute
    response = self.command_executor.execute(driver_command, params)
  File "C:\Python27\lib\site-packages\selenium-2.31.0-py2.7.egg\selenium\webdriver\remote\remote_connection.py", line 340, in execute
    return self._request(url, method=command_info[0], data=data)
  File "C:\Python27\lib\site-packages\selenium-2.31.0-py2.7.egg\selenium\webdriver\remote\remote_connection.py", line 387, in _request
    response = opener.open(request)
  File "C:\Python27\lib\urllib2.py", line 394, in open
    response = self._open(req, data)
  File "C:\Python27\lib\urllib2.py", line 412, in _open
    '_open', req)
  File "C:\Python27\lib\urllib2.py", line 372, in _call_chain
    result = func(*args)
  File "C:\Python27\lib\urllib2.py", line 1199, in http_open
    return self.do_open(httplib.HTTPConnection, req)
  File "C:\Python27\lib\urllib2.py", line 1174, in do_open
    raise URLError(err)
URLError: <urlopen error [Errno 10061] No connection could be made because the target machine actively refused it>
]]></error></testcase></testsuite>